Workbook

Sheet Findings
B1: Jackrabbit Class List — Reconciliation Findings
B2: Source: ClassesListReport.xls · 176 classes · exported 28 July 2026
B4: HEADLINE
C5: The categories DO support your nine service rows — with two structural exceptions you need to decide on.
C6: But this export contains NO 2023, 2024 or 2025 classes. It is the current session only.
B8: 1. Category 1 separates Rec from Team cleanly
C9: Recreational 155 · Team 18 · Staff 3. My earlier read off your screenshot was wrong — Cat1 is not
C10: uniformly 'Recreational'. It does carry the top-level split.
B12: 2. Category 2 is the service-level key
C13: Rec Girls 86 · Pre-School 36 · Rec Boys 12 · Tumble (Combined) 12 · Parent-Child 9 · blank 21.
C14: These map onto four of your rows with no ambiguity. Parent-Child (First Flight) folds into Preschool.
C15: The 21 blanks are exactly the 18 Team + 3 Staff classes — Team carries no Cat2 or Cat3 at all.
B17: 3. TEAM IS DOUBLE-ENROLLED BY DESIGN — the important one
C18: Only 7 of the 18 Team classes carry tuition. They are hour-tier billing groups:
C19: 1 Day $255 · 6 hrs $310 · 2 days $350 · 9 hrs $385 · 12 hr $440 · 16 hrs $485 · 20 hrs $543
C20: The other 11 are $0 containers — 'MAG Team 2026-27' (77 enrolled) plus practice groups (Xcel Silver/Gold/
C21: Platinum/Diamond, WDP L3/L4/Optionals, Mens Devo, Womens Devo).
C22: Team athletes sit in a billing group AND a practice group AND the roster. Summing enrollment across all 18
C23: would triple-count them. Team revenue = the 7 billing groups only (74 enrolled). Use practice groups for
C24: headcount and level mix, never for revenue.
C25: Consequence: you CANNOT split team revenue girls vs boys. Billing groups are gender-blind. Headcount can be
C26: inferred (Mens Devo 13 vs everything else) but the dollars cannot.
B28: 4. Pre-Team barely exists as a service line
C29: Only 2 classes are tagged PT in Cat3: 'Hot Shots' (Girls PT1, 9 enrolled, $310) and 'Boys Advanced 2 hr'
C30: (Boys PT2, 1 enrolled, $200). Both sit under Rec Girls / Rec Boys in Cat2, so I applied a Cat3 override.
C31: 10 students total. Consider folding this row into the rec rows — it will not carry a meaningful trend.
B33: 5. Summer Intensives are a separate product priced differently
C34: 11 classes in '2026 Summer Intensive' — the website's Summer Mini-Sessions. Flat 6-week fees ($183–$300),
C35: not monthly tuition. They carry the same Cat2 values as the year-round classes, so they will blend into
C36: your rec rows and distort Avg. Transaction Value unless separated. Flagged 'OK - summer session'.
B38: 6. Thirty-six classes carry $0 tuition
C39: 22 Recreational · 11 Team · 3 Staff. Waitlists, roster containers, practice groups and staff
C40: placeholders. Excluded from pricing via the 'Billable' column so they do not drag the averages to zero.
B42: 7. NO HISTORICAL DATA IN THIS EXPORT
C43: Session mix: 2026-27 Rec 144 · 2026-27 Team 18 · 2026 Summer Intensive 11 · 2025-26 Rec 1 · blank 2.
C44: There is not a single 2023, 2024 or 2025 class here. This file gives you current price and current
C45: enrollment — nothing for the three-year comparison.
C46: The 2023–2025 numbers must come from the revenue and transaction reports filtered by date range, not from
C47: the class list. Re-run the class list with archived sessions included if you also want historical prices.
B49: 8. Fill rate — a genuine finding, available right now
...

Sheet Class Export (mapped)
B1: Class Export — mapped to service rows
B4: Class | C4: Cat1 | D4: Cat2 | E4: Cat3 | F4: Session | G4: Status | H4: Instructors | I4: Days | J4: Start Time | K4: Duration | L4: Tuition | M4: Enrolled | N4: Max | O4: Cat Key | P4: Maps To | Q4: Billable | R4: Flag
B5: MAG Team 2026-27 | C5: Team | F5: 2026-27 Team | G5: Active | H5: Jamian W., Susan W., Rigel (Jonathan) L. | J5: 12:00am | K5: 12:00 | L5: 0 | M5: 77 | N5: 100 | O5: Team | (blank) | P5: Competitive -- American Flyers Teams | Q5: No | R5: TEAM PRACTICE GRP - $0
B6: Team 26-27 Xcel Gold 1 Practice Group | C6: Team | F6: 2026-27 Team | G6: Active | H6: Susan W., Rigel (Jonathan) L., Riley P., Maya L. | I6: TuThSu | L6: 0 | M6: 7 | N6: 10 | O6: Team | (blank) | P6: Competitive -- American Flyers Teams | Q6: No | R6: TEAM PRACTICE GRP - $0
B7: Team 26-27 Xcel Platinum2/Diamond Practice Group | C7: Team | F7: 2026-27 Team | G7: Active | H7: Susan W., Rigel (Jonathan) L., Kyla P., Jamian W. | I7: MTuWSu | L7: 0 | M7: 8 | N7: 10 | O7: Team | (blank) | P7: Competitive -- American Flyers Teams | Q7: No | R7: TEAM PRACTICE GRP - $0
B8: Team 26-27 Billing Group 1 Day | C8: Team | F8: 2026-27 Team | G8: Active | L8: 255 | M8: 1 | N8: 20 | O8: Team | (blank) | P8: Competitive -- American Flyers Teams | Q8: Yes | R8: OK
B9: Team 26-27 Billing Group 12hr | C9: Team | F9: 2026-27 Team | G9: Active | L9: 440 | M9: 25 | N9: 40 | O9: Team | (blank) | P9: Competitive -- American Flyers Teams | Q9: Yes | R9: OK
B10: Team 26-27 Billing Group 16hrs | C10: Team | F10: 2026-27 Team | G10: Active | L10: 485 | M10: 17 | N10: 30 | O10: Team | (blank) | P10: Competitive -- American Flyers Teams | Q10: Yes | R10: OK
B11: Team 26-27 Billing Group 2 days | C11: Team | F11: 2026-27 Team | G11: Active | L11: 350 | M11: 4 | N11: 20 | O11: Team | (blank) | P11: Competitive -- American Flyers Teams | Q11: Yes | R11: OK
B12: Team 26-27 Billing Group 20 hrs | C12: Team | F12: 2026-27 Team | G12: Active | L12: 543 | M12: 12 | N12: 15 | O12: Team | (blank) | P12: Competitive -- American Flyers Teams | Q12: Yes | R12: OK
B13: Team 26-27 Billing Group 6 hrs | C13: Team | F13: 2026-27 Team | G13: Active | L13: 310 | M13: 8 | N13: 20 | O13: Team | (blank) | P13: Competitive -- American Flyers Teams | Q13: Yes | R13: OK
B14: Team 26-27 Billing Group 9 hrs | C14: Team | F14: 2026-27 Team | G14: Active | L14: 385 | M14: 7 | N14: 20 | O14: Team | (blank) | P14: Competitive -- American Flyers Teams | Q14: Yes | R14: OK
B15: Team 26-27 Mens Devo | C15: Team | F15: 2026-27 Team | G15: Active | H15: Rigel (Jonathan) L., Jamian W., Ryan A. | I15: MTuWThFSaSu | J15: 3:30pm | K15: 4:00 | L15: 0 | M15: 13 | N15: 20 | O15: Team | (blank) | P15: Competitive -- American Flyers Teams | Q15: No | R15: TEAM PRACTICE GRP - $0
B16: Team 26-27 WDP L3 | C16: Team | F16: 2026-27 Team | G16: Active | H16: Denae C., Jamian W., Alexa A., Kyla P. | I16: TuThSa | L16: 0 | M16: 5 | N16: 20 | O16: Team | (blank) | P16: Competitive -- American Flyers Teams | Q16: No | R16: TEAM PRACTICE GRP - $0
B17: Team 26-27 WDP L4 | C17: Team | F17: 2026-27 Team | G17: Active | H17: Jamian W., Denae C., Alexa A., Kyla P. | I17: TuThSa | L17: 0 | M17: 9 | N17: 46 | O17: Team | (blank) | P17: Competitive -- American Flyers Teams | Q17: No | R17: TEAM PRACTICE GRP - $0
B18: Team 26-27 WDP Optionals | C18: Team | F18: 2026-27 Team | G18: Active | H18: Alexa A., Jamian W., Denae C. | I18: MTuWThSa | J18: 2:45pm | K18: 4:00 | L18: 0 | M18: 17 | N18: 25 | O18: Team | (blank) | P18: Competitive -- American Flyers Teams | Q18: No | R18: TEAM PRACTICE GRP - $0
B19: Team 26-27 Womens Devo | C19: Team | F19: 2026-27 Team | G19: Active | H19: Jamian W., Denae C., Alexa A., Kyla P. | L19: 0 | M19: 33 | N19: 50 | O19: Team | (blank) | P19: Competitive -- American Flyers Teams | Q19: No | R19: TEAM PRACTICE GRP - $0
B20: Team 26-27 Xcel | C20: Team | F20: 2026-27 Team | G20: Active | H20: Susan W., Jamian W., Kyla P., Rigel (Jonathan) L. | L20: 0 | M20: 31 | N20: 40 | O20: Team | (blank) | P20: Competitive -- American Flyers Teams | Q20: No | R20: TEAM PRACTICE GRP - $0
B21: Team 26-27 Xcel Gold2/Platinum 1 Practice Group | C21: Team | F21: 2026-27 Team | G21: Active | H21: Susan W., Rigel (Jonathan) L., Kyla P., Jamian W. | I21: MWSu | L21: 0 | M21: 9 | N21: 11 | O21: Team | (blank) | P21: Competitive -- American Flyers Teams | Q21: No | R21: TEAM PRACTICE GRP - $0
B22: Team 26-27 Xcel Silver Practice Group | C22: Team | F22: 2026-27 Team | G22: Active | H22: Susan W., Rigel (Jonathan) L., Jamian W., Kyla P. | I22: TuThSu | L22: 0 | M22: 5 | N22: 20 | O22: Team | (blank) | P22: Competitive -- American Flyers Teams | Q22: No | R22: TEAM PRACTICE GRP - $0
B23: Boys Advanced 2 hr | C23: Recreational | D23: Rec Boys | E23: Boys PT2 | F23: 2026-27 Rec | G23: Active | H23: Nyx W., MAG A. | J23: 5:30pm | K23: 2:00 | L23: 200 | M23: 1 | N23: 2 | O23: Recreational | Rec Boys | P23: Competitive -- Pre-Team | Q23: Yes | R23: OK
B24: Hot Shots | C24: Recreational | D24: Rec Girls | E24: Girls PT1 | F24: 2026-27 Rec | G24: Active | H24: Kyla P., Riley P., Jamian W., MAG A. | I24: MW | J24: 3:30pm | K24: 3:00 | L24: 310 | M24: 9 | N24: 10 | O24: Recreational | Rec Girls | P24: Competitive -- Pre-Team | Q24: Yes | R24: OK
B25: MAG STAFF | C25: Staff | F25: 2025-26 Rec | G25: Active | H25: Alexa A., Jamian W., Nicole E., Lisa (Alyssa) A. | I25: MTuWThFSaSu | L25: 0 | M25: 24 | N25: 150 | O25: Staff | (blank) | P25: EXCLUDE -- Staff placeholder | Q25: No | R25: EXCLUDED - not revenue
B26: Tuesday Staff | C26: Staff | G26: On Hold | H26: Jamian W. | I26: Tu | J26: 8:30am | K26: 12:00 | L26: 0 | M26: 0 | N26: 20 | O26: Staff | (blank) | P26: EXCLUDE -- Staff placeholder | Q26: No | R26: EXCLUDED - not revenue
B27: Wednesday Staff | C27: Staff | G27: On Hold | H27: Jamian W. | I27: W | J27: 8:30am | K27: 12:00 | L27: 0 | M27: 0 | N27: 20 | O27: Staff | (blank) | P27: EXCLUDE -- Staff placeholder | Q27: No | R27: EXCLUDED - not revenue
B28: Boys Red Wings M 3:45p | C28: Recreational | D28: Rec Boys | E28: Boys B1 | F28: 2026-27 Rec | G28: Active | H28: Abram K., MAG A. | I28: M | J28: 3:45pm | K28: 1:15 | L28: 143 | M28: 8 | N28: 8 | O28: Recreational | Rec Boys | P28: Recreational -- Boys Wings | Q28: Yes | R28: OK
B29: Boys Red Wings F 4:15p (5-7yrs) | C29: Recreational | D29: Rec Boys | E29: Boys B1 | F29: 2026-27 Rec | G29: Active | H29: Michael K., MAG A. | I29: F | J29: 4:15pm | K29: 1:15 | L29: 143 | M29: 3 | N29: 8 | O29: Recreational | Rec Boys | P29: Recreational -- Boys Wings | Q29: Yes | R29: OK
B30: Boys Red Wings F 5:45p | C30: Recreational | D30: Rec Boys | E30: Boys B1 | F30: 2026-27 Rec | G30: Active | H30: Michael K., MAG A. | I30: F | J30: 5:45pm | K30: 1:15 | L30: 143 | M30: 2 | N30: 8 | O30: Recreational | Rec Boys | P30: Recreational -- Boys Wings | Q30: Yes | R30: OK
B31: Boys Red Wings W 4:00p | C31: Recreational | D31: Rec Boys | E31: Boys B1 | F31: 2026-27 Rec | G31: Active | H31: Michael K., MAG A. | I31: W | J31: 4:00pm | K31: 1:15 | L31: 143 | M31: 3 | N31: 8 | O31: Recreational | Rec Boys | P31: Recreational -- Boys Wings | Q31: Yes | R31: OK
B32: Boys Red Wings W 5:30p | C32: Recreational | D32: Rec Boys | E32: Boys B1 | F32: 2026-27 Rec | G32: Active | H32: Michael K., MAG A. | I32: W | J32: 5:30pm | K32: 1:15 | L32: 143 | M32: 5 | N32: 8 | O32: Recreational | Rec Boys | P32: Recreational -- Boys Wings | Q32: Yes | R32: OK
B33: Boys Red Wings Waitlist | C33: Recreational | D33: Rec Boys | E33: Boys B1 | F33: 2026-27 Rec | G33: Active | L33: 0 | M33: 0 | N33: 0 | O33: Recreational | Rec Boys | P33: Recreational -- Boys Wings | Q33: No | R33: NO TUITION
B34: Boys Red Wings Waitlist-Level Adjustment | C34: Recreational | D34: Rec Boys | E34: Boys B1 | F34: 2026-27 Rec | G34: Active | L34: 0 | M34: 0 | N34: 0 | O34: Recreational | Rec Boys | P34: Recreational -- Boys Wings | Q34: No | R34: NO TUITION
B35: Boys White Wings Waitlist - Level Adjustment | C35: Recreational | D35: Rec Boys | E35: Boys B2 | F35: 2026-27 Rec | G35: Active | L35: 0 | M35: 0 | N35: 0 | O35: Recreational | Rec Boys | P35: Recreational -- Boys Wings | Q35: No | R35: NO TUITION
B36: Boys White Wings F 3:45p | C36: Recreational | D36: Rec Boys | E36: Boys B2 | F36: 2026-27 Rec | G36: Active | H36: Nyx W., MAG A. | I36: F | J36: 3:45pm | K36: 1:30 | L36: 167 | M36: 6 | N36: 8 | O36: Recreational | Rec Boys | P36: Recreational -- Boys Wings | Q36: Yes | R36: OK
B37: Boys White Wings Su 11:30a Starts 9/13 | C37: Recreational | D37: Rec Boys | E37: Boys B2 | F37: 2026-27 Rec | G37: Active | H37: Nyx W., MAG A. | I37: Su | J37: 11:30am | K37: 1:30 | L37: 167 | M37: 4 | N37: 8 | O37: Recreational | Rec Boys | P37: Recreational -- Boys Wings | Q37: Yes | R37: OK
B38: Summer 2026 Boys White Wings W 3:45 - 6 weeks | C38: Recreational | D38: Rec Boys | E38: Boys B2 | F38: 2026 Summer Intensive | G38: Active | H38: Kjeld N., MAG A. | I38: W | J38: 3:45pm | K38: 1:30 | L38: 250.5 | M38: 2 | N38: 8 | O38: Recreational | Rec Boys | P38: Recreational -- Boys Wings | Q38: Yes | R38: OK - summer session
B39: Kinder Red Wings M 3:45p | C39: Recreational | D39: Rec Girls | E39: Girls G1 | F39: 2026-27 Rec | G39: Active | H39: Faith F., MAG A. | I39: M | J39: 3:45pm | K39: 1:15 | L39: 143 | M39: 8 | N39: 8 | O39: Recreational | Rec Girls | P39: Recreational -- Girls Wings | Q39: Yes | R39: OK
B40: Kinder Red Wings M 5:00p | C40: Recreational | D40: Rec Girls | E40: Girls G1 | F40: 2026-27 Rec | G40: Active | H40: Ruthie G., MAG A. | I40: M | J40: 5:00pm | K40: 1:15 | L40: 143 | M40: 6 | N40: 8 | O40: Recreational | Rec Girls | P40: Recreational -- Girls Wings | Q40: Yes | R40: OK
B41: Kinder Red Wings S 11:45a starts 9/12 | C41: Recreational | D41: Rec Girls | E41: Girls G1 | F41: 2026-27 Rec | G41: Active | H41: Amelia K., MAG A. | I41: Sa | J41: 11:45am | K41: 1:15 | L41: 143 | M41: 7 | N41: 8 | O41: Recreational | Rec Girls | P41: Recreational -- Girls Wings | Q41: Yes | R41: OK
B42: Kinder Red Wings Su 3:00p starts 9/13 | C42: Recreational | D42: Rec Girls | E42: Girls G1 | F42: 2026-27 Rec | G42: Active | H42: Faith F., MAG A. | I42: Su | J42: 3:00pm | K42: 1:15 | L42: 143 | M42: 7 | N42: 8 | O42: Recreational | Rec Girls | P42: Recreational -- Girls Wings | Q42: Yes | R42: OK
...

Sheet Service Summary
B1: Service Summary — live from the Class Export tab
B2: Billable classes only ($0 and staff placeholders excluded from price columns)
B4: Service Row | C4: Classes | D4: Billable classes | E4: Enrolled | F4: Capacity | G4: Fill % | H4: Min monthly | I4: Avg monthly | J4: Max monthly
B5: Recreational -- Preschool (The Jungle) | C5: =COUNTIF('Class Export (mapped)'!$P$5:$P$180,$B5) -> 45 | D5: =COUNTIFS('Class Export (mapped)'!$P$5:$P$180,$B5,'Class Export (mapped)'!$Q$5:$Q$180,"Yes") -> 39 | E5: =SUMIF('Class Export (mapped)'!$P$5:$P$180,$B5,'Class Export (mapped)'!$M$5:$M$180) -> 211 | F5: =SUMIF('Class Export (mapped)'!$P$5:$P$180,$B5,'Class Export (mapped)'!$N$5:$N$180) -> 309 | G5: =IFERROR(E5/F5,0) -> 0.6828479 | H5: =IFERROR(_xlfn.MINIFS('Class Export (mapped)'!$L$5:$L$180,'Class Export (mapped)'!$P$5:$P$180,$B5,'Class Export (mapped)'!$Q$5:$Q$180,"Yes"),0) -> 114 | I5: =IFERROR(AVERAGEIFS('Class Export (mapped)'!$L$5:$L$180,'Class Export (mapped)'!$P$5:$P$180,$B5,'Class Export (mapped)'!$Q$5:$Q$180,"Yes"),0) -> 120.35897 | J5: =IFERROR(_xlfn.MAXIFS('Class Export (mapped)'!$L$5:$L$180,'Class Export (mapped)'!$P$5:$P$180,$B5,'Class Export (mapped)'!$Q$5:$Q$180,"Yes"),0) -> 122
B6: Recreational -- Girls Wings | C6: =COUNTIF('Class Export (mapped)'!$P$5:$P$180,$B6) -> 85 | D6: =COUNTIFS('Class Export (mapped)'!$P$5:$P$180,$B6,'Class Export (mapped)'!$Q$5:$Q$180,"Yes") -> 75 | E6: =SUMIF('Class Export (mapped)'!$P$5:$P$180,$B6,'Class Export (mapped)'!$M$5:$M$180) -> 402 | F6: =SUMIF('Class Export (mapped)'!$P$5:$P$180,$B6,'Class Export (mapped)'!$N$5:$N$180) -> 579 | G6: =IFERROR(E6/F6,0) -> 0.69430052 | H6: =IFERROR(_xlfn.MINIFS('Class Export (mapped)'!$L$5:$L$180,'Class Export (mapped)'!$P$5:$P$180,$B6,'Class Export (mapped)'!$Q$5:$Q$180,"Yes"),0) -> 143 | I6: =IFERROR(AVERAGEIFS('Class Export (mapped)'!$L$5:$L$180,'Class Export (mapped)'!$P$5:$P$180,$B6,'Class Export (mapped)'!$Q$5:$Q$180,"Yes"),0) -> 176.19333 | J6: =IFERROR(_xlfn.MAXIFS('Class Export (mapped)'!$L$5:$L$180,'Class Export (mapped)'!$P$5:$P$180,$B6,'Class Export (mapped)'!$Q$5:$Q$180,"Yes"),0) -> 300
B7: Recreational -- Boys Wings | C7: =COUNTIF('Class Export (mapped)'!$P$5:$P$180,$B7) -> 11 | D7: =COUNTIFS('Class Export (mapped)'!$P$5:$P$180,$B7,'Class Export (mapped)'!$Q$5:$Q$180,"Yes") -> 8 | E7: =SUMIF('Class Export (mapped)'!$P$5:$P$180,$B7,'Class Export (mapped)'!$M$5:$M$180) -> 33 | F7: =SUMIF('Class Export (mapped)'!$P$5:$P$180,$B7,'Class Export (mapped)'!$N$5:$N$180) -> 64 | G7: =IFERROR(E7/F7,0) -> 0.515625 | H7: =IFERROR(_xlfn.MINIFS('Class Export (mapped)'!$L$5:$L$180,'Class Export (mapped)'!$P$5:$P$180,$B7,'Class Export (mapped)'!$Q$5:$Q$180,"Yes"),0) -> 143 | I7: =IFERROR(AVERAGEIFS('Class Export (mapped)'!$L$5:$L$180,'Class Export (mapped)'!$P$5:$P$180,$B7,'Class Export (mapped)'!$Q$5:$Q$180,"Yes"),0) -> 162.4375 | J7: =IFERROR(_xlfn.MAXIFS('Class Export (mapped)'!$L$5:$L$180,'Class Export (mapped)'!$P$5:$P$180,$B7,'Class Export (mapped)'!$Q$5:$Q$180,"Yes"),0) -> 250.5
B8: Recreational -- Tumbling | C8: =COUNTIF('Class Export (mapped)'!$P$5:$P$180,$B8) -> 12 | D8: =COUNTIFS('Class Export (mapped)'!$P$5:$P$180,$B8,'Class Export (mapped)'!$Q$5:$Q$180,"Yes") -> 9 | E8: =SUMIF('Class Export (mapped)'!$P$5:$P$180,$B8,'Class Export (mapped)'!$M$5:$M$180) -> 62 | F8: =SUMIF('Class Export (mapped)'!$P$5:$P$180,$B8,'Class Export (mapped)'!$N$5:$N$180) -> 76 | G8: =IFERROR(E8/F8,0) -> 0.81578947 | H8: =IFERROR(_xlfn.MINIFS('Class Export (mapped)'!$L$5:$L$180,'Class Export (mapped)'!$P$5:$P$180,$B8,'Class Export (mapped)'!$Q$5:$Q$180,"Yes"),0) -> 122 | I8: =IFERROR(AVERAGEIFS('Class Export (mapped)'!$L$5:$L$180,'Class Export (mapped)'!$P$5:$P$180,$B8,'Class Export (mapped)'!$Q$5:$Q$180,"Yes"),0) -> 142.33333 | J8: =IFERROR(_xlfn.MAXIFS('Class Export (mapped)'!$L$5:$L$180,'Class Export (mapped)'!$P$5:$P$180,$B8,'Class Export (mapped)'!$Q$5:$Q$180,"Yes"),0) -> 183
B9: Competitive -- Pre-Team | C9: =COUNTIF('Class Export (mapped)'!$P$5:$P$180,$B9) -> 2 | D9: =COUNTIFS('Class Export (mapped)'!$P$5:$P$180,$B9,'Class Export (mapped)'!$Q$5:$Q$180,"Yes") -> 2 | E9: =SUMIF('Class Export (mapped)'!$P$5:$P$180,$B9,'Class Export (mapped)'!$M$5:$M$180) -> 10 | F9: =SUMIF('Class Export (mapped)'!$P$5:$P$180,$B9,'Class Export (mapped)'!$N$5:$N$180) -> 12 | G9: =IFERROR(E9/F9,0) -> 0.83333333 | H9: =IFERROR(_xlfn.MINIFS('Class Export (mapped)'!$L$5:$L$180,'Class Export (mapped)'!$P$5:$P$180,$B9,'Class Export (mapped)'!$Q$5:$Q$180,"Yes"),0) -> 200 | I9: =IFERROR(AVERAGEIFS('Class Export (mapped)'!$L$5:$L$180,'Class Export (mapped)'!$P$5:$P$180,$B9,'Class Export (mapped)'!$Q$5:$Q$180,"Yes"),0) -> 255 | J9: =IFERROR(_xlfn.MAXIFS('Class Export (mapped)'!$L$5:$L$180,'Class Export (mapped)'!$P$5:$P$180,$B9,'Class Export (mapped)'!$Q$5:$Q$180,"Yes"),0) -> 310
B10: Competitive -- American Flyers Teams | C10: =COUNTIF('Class Export (mapped)'!$P$5:$P$180,$B10) -> 18 | D10: =COUNTIFS('Class Export (mapped)'!$P$5:$P$180,$B10,'Class Export (mapped)'!$Q$5:$Q$180,"Yes") -> 7 | E10: =SUMIF('Class Export (mapped)'!$P$5:$P$180,$B10,'Class Export (mapped)'!$M$5:$M$180) -> 288 | F10: =SUMIF('Class Export (mapped)'!$P$5:$P$180,$B10,'Class Export (mapped)'!$N$5:$N$180) -> 517 | G10: =IFERROR(E10/F10,0) -> 0.55705996 | H10: =IFERROR(_xlfn.MINIFS('Class Export (mapped)'!$L$5:$L$180,'Class Export (mapped)'!$P$5:$P$180,$B10,'Class Export (mapped)'!$Q$5:$Q$180,"Yes"),0) -> 255 | I10: =IFERROR(AVERAGEIFS('Class Export (mapped)'!$L$5:$L$180,'Class Export (mapped)'!$P$5:$P$180,$B10,'Class Export (mapped)'!$Q$5:$Q$180,"Yes"),0) -> 395.42857 | J10: =IFERROR(_xlfn.MAXIFS('Class Export (mapped)'!$L$5:$L$180,'Class Export (mapped)'!$P$5:$P$180,$B10,'Class Export (mapped)'!$Q$5:$Q$180,"Yes"),0) -> 543
B11: EXCLUDE -- Staff placeholder | C11: =COUNTIF('Class Export (mapped)'!$P$5:$P$180,$B11) -> 3 | D11: =COUNTIFS('Class Export (mapped)'!$P$5:$P$180,$B11,'Class Export (mapped)'!$Q$5:$Q$180,"Yes") -> 0 | E11: =SUMIF('Class Export (mapped)'!$P$5:$P$180,$B11,'Class Export (mapped)'!$M$5:$M$180) -> 24 | F11: =SUMIF('Class Export (mapped)'!$P$5:$P$180,$B11,'Class Export (mapped)'!$N$5:$N$180) -> 190 | G11: =IFERROR(E11/F11,0) -> 0.12631579 | H11: =IFERROR(_xlfn.MINIFS('Class Export (mapped)'!$L$5:$L$180,'Class Export (mapped)'!$P$5:$P$180,$B11,'Class Export (mapped)'!$Q$5:$Q$180,"Yes"),0) -> 0 | I11: =IFERROR(AVERAGEIFS('Class Export (mapped)'!$L$5:$L$180,'Class Export (mapped)'!$P$5:$P$180,$B11,'Class Export (mapped)'!$Q$5:$Q$180,"Yes"),0) -> 0 | J11: =IFERROR(_xlfn.MAXIFS('Class Export (mapped)'!$L$5:$L$180,'Class Export (mapped)'!$P$5:$P$180,$B11,'Class Export (mapped)'!$Q$5:$Q$180,"Yes"),0) -> 0
B12: TOTAL (excl. staff placeholders) | C12: =SUM(C5:C10) -> 173 | D12: =SUM(D5:D10) -> 140 | E12: =SUM(E5:E10) -> 1006 | F12: =SUM(F5:F10) -> 1557 | G12: =IFERROR(E12/F12,0) -> 0.64611432
B14: Reading these numbers
B15: Team enrolled counts the 7 billing groups plus the 11 $0 practice/roster groups, so it overstates unique athletes.
B16: Unique team athletes = the 'MAG Team 2026-27' roster (77). Billing-group enrolment totals 74.
B17: Tuition is monthly except the 11 Summer Intensive classes, which are flat 6-week fees.
B18: Source: Jackrabbit Class List export, 176 classes, 28 July 2026. Mapping rules on the Crosswalk tab.

Sheet Crosswalk
B1: Mapping rules applied
B4: Cat1 | C4: Cat2 | D4: Cat3 override | E4: Maps to service row | F4: Classes
B5: Recreational | C5: Pre-School | D5: — | E5: Recreational -- Preschool (The Jungle) | F5: 36
B6: Recreational | C6: Parent-Child | D6: — | E6: Recreational -- Preschool (The Jungle) | F6: 9
B7: Recreational | C7: Rec Girls | D7: — | E7: Recreational -- Girls Wings | F7: 85
B8: Recreational | C8: Rec Boys | D8: — | E8: Recreational -- Boys Wings | F8: 11
B9: Recreational | C9: Tumble (Combined) | D9: — | E9: Recreational -- Tumbling | F9: 12
B10: Recreational | C10: Rec Girls | D10: Girls PT1 | E10: Competitive -- Pre-Team | F10: 1
B11: Recreational | C11: Rec Boys | D11: Boys PT2 | E11: Competitive -- Pre-Team | F11: 1
B12: Team | C12: (blank) | D12: — | E12: Competitive -- American Flyers Teams | F12: 18
B13: Staff | C13: (blank) | D13: — | E13: EXCLUDE -- Staff placeholder | F13: 3
B15: Rows not yet in your nine-row structure:
B16: Ancillary -- Open Gym · Ancillary -- Annual Membership Fees · Events -- American Flyers Cup
B17: None of these are classes, so they do not appear in this export. They live in the transaction sub-types instead.
